<robot
  name="sd700e_grip" xmlns:xacro="http://ros.org/wiki/xacro">
  
  <link name="base_footprint"/>
  <joint name="base_footprint_to_base" type="fixed">
    <axis rpy="0 0 0" xyz="0 0 0"/>
    <parent link="base_footprint"/>
    <child link="base_link"/>
    <origin rpy="0 0 0" xyz="0 0 0"/>
  </joint>

  <link
    name="base_link">
    <inertial>
      <origin
        xyz="-0.0194690222590367 0.0669003838868867 0.00026918811932978"
        rpy="0 0 0" />
      <mass
        value="0.001" />
      <inertia
        ixx="10"
        ixy="0"
        ixz="0"
        iyy="10"
        iyz="0"
        izz="10" />
    </inertial>
    <visual>
      <origin
        xyz="0 0 0"
        rpy="0 0 0" />
      <geometry>
        <mesh
          filename="package://sd700e_grip/meshes/base_link.STL" />
      </geometry>
      <material
        name="">
        <color
          rgba="1.0 0.42353 0.03921 1.0" />
      </material>
    </visual>
    <collision>
      <origin
        xyz="0 0 0"
        rpy="0 0 0" />
      <geometry>
        <mesh
          filename="package://sd700e_grip/meshes/base_link.STL" />
      </geometry>
    </collision>
  </link>
  <link
    name="Link1">
    <inertial>
      <origin
        xyz="6.24979525564542E-05 -0.0250389972697368 -3.54756695346475E-05"
        rpy="0 0 0" />
      <mass
        value="0.00001" />
      <inertia
        ixx="10"
        ixy="0"
        ixz="0"
        iyy="10"
        iyz="0"
        izz="10" />
    </inertial>
    <visual>
      <origin
        xyz="0 0 0"
        rpy="0 0 0" />
      <geometry>
        <mesh
          filename="package://sd700e_grip/meshes/Link1.STL" />
      </geometry>
      <material
        name="">
        <color
          rgba="1.0 0.42353 0.03921 1.0" />
      </material>
    </visual>
    <collision>
      <origin
        xyz="0 0 0"
        rpy="0 0 0" />
      <geometry>
        <mesh
          filename="package://sd700e_grip/meshes/Link1.STL" />
      </geometry>
    </collision>
  </link>
  <joint
    name="Joint1"
    type="revolute">
    <origin
      xyz="0 0 0.263"
      rpy="1.5708 0 0" />
    <parent
      link="base_link" />
    <child
      link="Link1" />
    <axis
      xyz="0 1 0" />
    <limit
      lower="-2.967"
      upper="2.967"
      effort="100"
      velocity="1" />
  </joint>
  <link
    name="Link2">
    <inertial>
      <origin
        xyz="3.89335646288233E-06 0.14379865823793 -0.0506443388040001"
        rpy="0 0 0" />
      <mass
        value="0.00001" />
      <inertia
        ixx="10"
        ixy="0"
        ixz="0"
        iyy="10"
        iyz="0"
        izz="10" />
    </inertial>
    <visual>
      <origin
        xyz="0 0 0"
        rpy="0 0 0" />
      <geometry>
        <mesh
          filename="package://sd700e_grip/meshes/Link2.STL" />
      </geometry>
      <material
        name="">
        <color
          rgba="1.0 0.42353 0.03921 1.0" />
      </material>
    </visual>
    <collision>
      <origin
        xyz="0 0 0"
        rpy="0 0 0" />
      <geometry>
        <mesh
          filename="package://sd700e_grip/meshes/Link2.STL" />
      </geometry>
    </collision>
  </link>
  <joint
    name="Joint2"
    type="revolute">
    <origin
      xyz="0 0 0"
      rpy="0 0 0" />
    <parent
      link="Link1" />
    <child
      link="Link2" />
    <axis
      xyz="0 0 1" />
    <limit
      lower="-1.9199"
      upper="1.9199"
      effort="100"
      velocity="1" />
  </joint>
  <link
    name="Link3">
    <inertial>
      <origin
        xyz="0.013415824980232 -0.0105511175519905 0.00078367779449206"
        rpy="0 0 0" />
      <mass
        value="0.00001" />
      <inertia
        ixx="10"
        ixy="0"
        ixz="0"
        iyy="10"
        iyz="0"
        izz="10" />
    </inertial>
    <visual>
      <origin
        xyz="0 0 0"
        rpy="0 0 0" />
      <geometry>
        <mesh
          filename="package://sd700e_grip/meshes/Link3.STL" />
      </geometry>
      <material
        name="">
        <color
          rgba="1.0 0.42353 0.03921 1.0" />
      </material>
    </visual>
    <collision>
      <origin
        xyz="0 0 0"
        rpy="0 0 0" />
      <geometry>
        <mesh
          filename="package://sd700e_grip/meshes/Link3.STL" />
      </geometry>
    </collision>
  </link>
  <joint
    name="Joint3"
    type="revolute">
    <origin
      xyz="0 0.35 0"
      rpy="0 0 0" />
    <parent
      link="Link2" />
    <child
      link="Link3" />
    <axis
      xyz="0 0 1" />
    <limit
      lower="-0.6981"
      upper="3.8397"
      effort="100"
      velocity="1" />
  </joint>
  <link
    name="Link4">
    <inertial>
      <origin
        xyz="0.124377414524302 0.000531054308674062 0.00764519285380822"
        rpy="0 0 0" />
      <mass
        value="0.00001" />
      <inertia
        ixx="10"
        ixy="0"
        ixz="0"
        iyy="10"
        iyz="0"
        izz="10" />
    </inertial>
    <visual>
      <origin
        xyz="0 0 0"
        rpy="0 0 0" />
      <geometry>
        <mesh
          filename="package://sd700e_grip/meshes/Link4.STL" />
      </geometry>
      <material
        name="">
        <color
          rgba="1.0 0.42353 0.03921 1.0" />
      </material>
    </visual>
    <collision>
      <origin
        xyz="0 0 0"
        rpy="0 0 0" />
      <geometry>
        <mesh
          filename="package://sd700e_grip/meshes/Link4.STL" />
      </geometry>
    </collision>
  </link>
  <joint
    name="Joint4"
    type="revolute">
    <origin
      xyz="0.0805 0 0"
      rpy="0 0 0" />
    <parent
      link="Link3" />
    <child
      link="Link4" />
    <axis
      xyz="1 0 0" />
    <limit
      lower="-3.1416"
      upper="3.1416"
      effort="100"
      velocity="1" />
  </joint>
  <link
    name="Link5">
    <inertial>
      <origin
        xyz="0.0171365648416463 5.00386109847373E-06 0.00579159804548859"
        rpy="0 0 0" />
      <mass
        value="0.00001" />
      <inertia
        ixx="10"
        ixy="0"
        ixz="0"
        iyy="10"
        iyz="0"
        izz="10" />
    </inertial>
    <visual>
      <origin
        xyz="0 0 0"
        rpy="0 0 0" />
      <geometry>
        <mesh
          filename="package://sd700e_grip/meshes/Link5.STL" />
      </geometry>
      <material
        name="">
        <color
          rgba="1.0 0.42353 0.03921 1.0" />
      </material>
    </visual>
    <collision>
      <origin
        xyz="0 0 0"
        rpy="0 0 0" />
      <geometry>
        <mesh
          filename="package://sd700e_grip/meshes/Link5.STL" />
      </geometry>
    </collision>
  </link>
  <joint
    name="Joint5"
    type="revolute">
    <origin
      xyz="0.2695 0 0"
      rpy="0 0 0" />
    <parent
      link="Link4" />
    <child
      link="Link5" />
    <axis
      xyz="0 0 1" />
    <limit
      lower="-2.1817"
      upper="2.1817"
      effort="100"
      velocity="1" />
  </joint>
  <link
    name="Link6">
    <inertial>
      <origin
        xyz="0.0688522601103922 -0.00341730826575071 -8.58713696627559E-05"
        rpy="0 0 0" />
      <mass
        value="0.00001" />
      <inertia
        ixx="10"
        ixy="0"
        ixz="0"
        iyy="10"
        iyz="0"
        izz="10" />
    </inertial>
    <visual>
      <origin
        xyz="0 0 0"
        rpy="0 0 0" />
      <geometry>
        <mesh
          filename="package://sd700e_grip/meshes/Link6.STL" />
      </geometry>
      <material
        name="">
        <color
          rgba="1 1 1 1" />
      </material>
    </visual>
    <collision>
      <origin
        xyz="0 0 0"
        rpy="0 0 0" />
      <geometry>
        <mesh
          filename="package://sd700e_grip/meshes/Link6.STL" />
      </geometry>
    </collision>
  </link>
  <joint
    name="Joint6"
    type="revolute">
    <origin
      xyz="0.0745 0 0"
      rpy="0 0 0" />
    <parent
      link="Link5" />
    <child
      link="Link6" />
    <axis
      xyz="1 0 0" />
    <limit
      lower="-3.1416"
      upper="3.1416"
      effort="100"
      velocity="1" />
  </joint>
  <link
    name="left_grip">
    <inertial>
      <origin
        xyz="0.0141086137554788 0 0.0169130859525959"
        rpy="0 0 0" />
      <mass
        value="0.00001" />
      <inertia
        ixx="10"
        ixy="0"
        ixz="0"
        iyy="10"
        iyz="0"
        izz="10" />
    </inertial>
    <visual>
      <origin
        xyz="0 0 0"
        rpy="0 0 0" />
      <geometry>
        <mesh
          filename="package://sd700e_grip/meshes/left_grip.STL" />
      </geometry>
      <material
        name="">
        <color
          rgba="0.749019607843137 0.749019607843137 0.749019607843137 1" />
      </material>
    </visual>
    <collision>
      <origin
        xyz="0 0 0"
        rpy="0 0 0" />
      <geometry>
        <mesh
          filename="package://sd700e_grip/meshes/left_grip.STL" />
      </geometry>
    </collision>
  </link>
  <joint
    name="leftjoint"
    type="prismatic">
    <origin
      xyz="0.1228 0 0"
      rpy="0 0 0" />
    <parent
      link="Link6" />
    <child
      link="left_grip" />
    <axis
      xyz="0 0 1" />
    <limit
      lower="-0.0035"
      upper="0.0035"
      effort="100"
      velocity="1" />
  </joint>
  <link
    name="right_grip">
    <inertial>
      <origin
        xyz="0.0141086137554787 7.7715611723761E-16 -0.016913085952596"
        rpy="0 0 0" />
      <mass
        value="0.00001" />
      <inertia
        ixx="10"
        ixy="0"
        ixz="0"
        iyy="10"
        iyz="0"
        izz="10" />
    </inertial>
    <visual>
      <origin
        xyz="0 0 0"
        rpy="0 0 0" />
      <geometry>
        <mesh
          filename="package://sd700e_grip/meshes/right_grip.STL" />
      </geometry>
      <material
        name="">
        <color
          rgba="0.749019607843137 0.749019607843137 0.749019607843137 1" />
      </material>
    </visual>
    <collision>
      <origin
        xyz="0 0 0"
        rpy="0 0 0" />
      <geometry>
        <mesh
          filename="package://sd700e_grip/meshes/right_grip.STL" />
      </geometry>
    </collision>
  </link>
  <joint
    name="rightjoint"
    type="prismatic">
    <origin
      xyz="0.1228 0 0"
      rpy="0 0 0" />
    <parent
      link="Link6" />
    <child
      link="right_grip" />
    <axis
      xyz="0 0 1" />
    <limit
      lower="-0.0035"
      upper="0.0035"
      effort="100"
      velocity="1" />
    <mimic joint="leftjoint" multiplier="-1" />
  </joint>
 

  <!-- Transmissions for ROS Control -->
  <xacro:macro name="transmission_block" params="joint_name">
    <transmission name="tran1">
      <type>transmission_interface/SimpleTransmission</type>
      <joint name="${joint_name}">
        <hardwareInterface>hardware_interface/PositionJointInterface</hardwareInterface>
      </joint>
      <actuator name="motor1">
        <hardwareInterface>hardware_interface/PositionJointInterface</hardwareInterface>
        <mechanicalReduction>1</mechanicalReduction>
      </actuator>
    </transmission>
  </xacro:macro>
  
  <xacro:transmission_block joint_name="Joint1"/>
  <xacro:transmission_block joint_name="Joint2"/>
  <xacro:transmission_block joint_name="Joint3"/>
  <xacro:transmission_block joint_name="Joint4"/>
  <xacro:transmission_block joint_name="Joint5"/>
  <xacro:transmission_block joint_name="Joint6"/>

  <!-- ros_control plugin -->
  <gazebo>
    <plugin name="gazebo_ros_control" filename="libgazebo_ros_control.so">
      <robotNamespace>/sd700e_grip</robotNamespace>
      <robotSimType>gazebo_ros_control/DefaultRobotHWSim</robotSimType>
      <legacyModeNS>true</legacyModeNS>
    </plugin>
  </gazebo>

</robot>
